[2025-10-19T12:26:57.474+0000] {local_task_job_runner.py:120} INFO - ::group::Pre task execution logs
[2025-10-19T12:26:57.524+0000] {taskinstance.py:2073} INFO - Dependencies all met for dep_context=non-requeueable deps ti=<TaskInstance: wiki_trending_pipeline.categorize_pages scheduled__2025-10-18T00:00:00+00:00 [queued]>
[2025-10-19T12:26:57.534+0000] {taskinstance.py:2073} INFO - Dependencies all met for dep_context=requeueable deps ti=<TaskInstance: wiki_trending_pipeline.categorize_pages scheduled__2025-10-18T00:00:00+00:00 [queued]>
[2025-10-19T12:26:57.535+0000] {taskinstance.py:2303} INFO - Starting attempt 2 of 3
[2025-10-19T12:26:57.550+0000] {taskinstance.py:2327} INFO - Executing <Task(PythonOperator): categorize_pages> on 2025-10-18 00:00:00+00:00
[2025-10-19T12:26:57.562+0000] {standard_task_runner.py:63} INFO - Started process 767 to run task
[2025-10-19T12:26:57.565+0000] {standard_task_runner.py:90} INFO - Running: ['***', 'tasks', 'run', 'wiki_trending_pipeline', 'categorize_pages', 'scheduled__2025-10-18T00:00:00+00:00', '--job-id', '10', '--raw', '--subdir', 'DAGS_FOLDER/wiki_top_pages_dag.py', '--cfg-path', '/tmp/tmp2djhfqp_']
[2025-10-19T12:26:57.568+0000] {standard_task_runner.py:91} INFO - Job 10: Subtask categorize_pages
[2025-10-19T12:26:57.647+0000] {task_command.py:426} INFO - Running <TaskInstance: wiki_trending_pipeline.categorize_pages scheduled__2025-10-18T00:00:00+00:00 [running]> on host 6045c73eb554
[2025-10-19T12:26:57.783+0000] {taskinstance.py:2644} INFO - Exporting env vars: AIRFLOW_CTX_DAG_OWNER='data-engineering' AIRFLOW_CTX_DAG_ID='wiki_trending_pipeline' AIRFLOW_CTX_TASK_ID='categorize_pages' AIRFLOW_CTX_EXECUTION_DATE='2025-10-18T00:00:00+00:00' AIRFLOW_CTX_TRY_NUMBER='2' AIRFLOW_CTX_DAG_RUN_ID='scheduled__2025-10-18T00:00:00+00:00'
[2025-10-19T12:26:57.784+0000] {taskinstance.py:430} INFO - ::endgroup::
[2025-10-19T12:26:57.851+0000] {logging_mixin.py:188} INFO - ‚ùå Ollama not accessible: HTTPConnectionPool(host='host.docker.internal', port=11434): Max retries exceeded with url: /api/tags (Caused by NewConnectionError('<urllib3.connection.HTTPConnection object at 0x7cc1df0298d0>: Failed to establish a new connection: [Errno -2] Name or service not known'))
[2025-10-19T12:26:57.851+0000] {logging_mixin.py:188} INFO -    Make sure to run: ollama serve
[2025-10-19T12:26:57.852+0000] {taskinstance.py:441} INFO - ::group::Post task execution logs
[2025-10-19T12:26:57.852+0000] {taskinstance.py:2890} ERROR - Task failed with exception
Traceback (most recent call last):
  File "/home/airflow/.local/lib/python3.11/site-packages/airflow/models/taskinstance.py", line 465, in _execute_task
    result = _execute_callable(context=context, **execute_callable_kwargs)
             ^^^^^^^^^^^^^^^^^^^^^^^^^^^^^^^^^^^^^^^^^^^^^^^^^^^^^^^^^^^^^
  File "/home/airflow/.local/lib/python3.11/site-packages/airflow/models/taskinstance.py", line 432, in _execute_callable
    return execute_callable(context=context, **execute_callable_kwargs)
           ^^^^^^^^^^^^^^^^^^^^^^^^^^^^^^^^^^^^^^^^^^^^^^^^^^^^^^^^^^^^
  File "/home/airflow/.local/lib/python3.11/site-packages/airflow/models/baseoperator.py", line 400, in wrapper
    return func(self, *args, **kwargs)
           ^^^^^^^^^^^^^^^^^^^^^^^^^^^
  File "/home/airflow/.local/lib/python3.11/site-packages/airflow/operators/python.py", line 235, in execute
    return_value = self.execute_callable()
                   ^^^^^^^^^^^^^^^^^^^^^^^
  File "/home/airflow/.local/lib/python3.11/site-packages/airflow/operators/python.py", line 252, in execute_callable
    return self.python_callable(*self.op_args, **self.op_kwargs)
           ^^^^^^^^^^^^^^^^^^^^^^^^^^^^^^^^^^^^^^^^^^^^^^^^^^^^^
  File "/opt/airflow/plugins/utils/categorize_pages.py", line 30, in categorize_pages
    raise Exception("Ollama not running. Start with: ollama serve")
Exception: Ollama not running. Start with: ollama serve
[2025-10-19T12:26:57.874+0000] {taskinstance.py:1205} INFO - Marking task as UP_FOR_RETRY. dag_id=wiki_trending_pipeline, task_id=categorize_pages, execution_date=20251018T000000, start_date=20251019T122657, end_date=20251019T122657
[2025-10-19T12:26:57.893+0000] {standard_task_runner.py:110} ERROR - Failed to execute job 10 for task categorize_pages (Ollama not running. Start with: ollama serve; 767)
[2025-10-19T12:26:57.938+0000] {local_task_job_runner.py:240} INFO - Task exited with return code 1
[2025-10-19T12:26:58.003+0000] {taskinstance.py:3482} INFO - 0 downstream tasks scheduled from follow-on schedule check
[2025-10-19T12:26:58.005+0000] {local_task_job_runner.py:222} INFO - ::endgroup::
[2025-10-19T18:09:21.498+0000] {local_task_job_runner.py:120} INFO - ::group::Pre task execution logs
[2025-10-19T18:09:21.611+0000] {taskinstance.py:2073} INFO - Dependencies all met for dep_context=non-requeueable deps ti=<TaskInstance: wiki_trending_pipeline.categorize_pages scheduled__2025-10-18T00:00:00+00:00 [queued]>
[2025-10-19T18:09:21.633+0000] {taskinstance.py:2073} INFO - Dependencies all met for dep_context=requeueable deps ti=<TaskInstance: wiki_trending_pipeline.categorize_pages scheduled__2025-10-18T00:00:00+00:00 [queued]>
[2025-10-19T18:09:21.634+0000] {taskinstance.py:2303} INFO - Starting attempt 2 of 3
[2025-10-19T18:09:21.661+0000] {taskinstance.py:2327} INFO - Executing <Task(PythonOperator): categorize_pages> on 2025-10-18 00:00:00+00:00
[2025-10-19T18:09:21.677+0000] {standard_task_runner.py:63} INFO - Started process 1338 to run task
[2025-10-19T18:09:21.683+0000] {standard_task_runner.py:90} INFO - Running: ['***', 'tasks', 'run', 'wiki_trending_pipeline', 'categorize_pages', 'scheduled__2025-10-18T00:00:00+00:00', '--job-id', '15', '--raw', '--subdir', 'DAGS_FOLDER/wiki_top_pages_dag.py', '--cfg-path', '/tmp/tmpx28tqkc6']
[2025-10-19T18:09:21.687+0000] {standard_task_runner.py:91} INFO - Job 15: Subtask categorize_pages
[2025-10-19T18:09:21.784+0000] {task_command.py:426} INFO - Running <TaskInstance: wiki_trending_pipeline.categorize_pages scheduled__2025-10-18T00:00:00+00:00 [running]> on host fd86742dd253
[2025-10-19T18:09:23.107+0000] {taskinstance.py:2644} INFO - Exporting env vars: AIRFLOW_CTX_DAG_OWNER='data-engineering' AIRFLOW_CTX_DAG_ID='wiki_trending_pipeline' AIRFLOW_CTX_TASK_ID='categorize_pages' AIRFLOW_CTX_EXECUTION_DATE='2025-10-18T00:00:00+00:00' AIRFLOW_CTX_TRY_NUMBER='2' AIRFLOW_CTX_DAG_RUN_ID='scheduled__2025-10-18T00:00:00+00:00'
[2025-10-19T18:09:23.108+0000] {taskinstance.py:430} INFO - ::endgroup::
[2025-10-19T18:09:23.155+0000] {logging_mixin.py:188} INFO - ‚úÖ Ollama is running on host
[2025-10-19T18:09:23.200+0000] {logging_mixin.py:188} INFO - üìä Categorizing: cleaned_2025_10_18.csv
[2025-10-19T18:09:23.484+0000] {logging_mixin.py:188} INFO - ‚úì Bucket 'gold' exists
[2025-10-19T18:09:23.615+0000] {logging_mixin.py:188} INFO - ‚úì Loaded 996 pages
[2025-10-19T18:09:23.616+0000] {logging_mixin.py:188} INFO - ü§ñ Classifying with Ollama...
[2025-10-19T18:09:23.628+0000] {taskinstance.py:441} INFO - ::group::Post task execution logs
[2025-10-19T18:09:23.631+0000] {taskinstance.py:2890} ERROR - Task failed with exception
Traceback (most recent call last):
  File "/home/airflow/.local/lib/python3.11/site-packages/airflow/models/taskinstance.py", line 465, in _execute_task
    result = _execute_callable(context=context, **execute_callable_kwargs)
             ^^^^^^^^^^^^^^^^^^^^^^^^^^^^^^^^^^^^^^^^^^^^^^^^^^^^^^^^^^^^^
  File "/home/airflow/.local/lib/python3.11/site-packages/airflow/models/taskinstance.py", line 432, in _execute_callable
    return execute_callable(context=context, **execute_callable_kwargs)
           ^^^^^^^^^^^^^^^^^^^^^^^^^^^^^^^^^^^^^^^^^^^^^^^^^^^^^^^^^^^^
  File "/home/airflow/.local/lib/python3.11/site-packages/airflow/models/baseoperator.py", line 400, in wrapper
    return func(self, *args, **kwargs)
           ^^^^^^^^^^^^^^^^^^^^^^^^^^^
  File "/home/airflow/.local/lib/python3.11/site-packages/airflow/operators/python.py", line 235, in execute
    return_value = self.execute_callable()
                   ^^^^^^^^^^^^^^^^^^^^^^^
  File "/home/airflow/.local/lib/python3.11/site-packages/airflow/operators/python.py", line 252, in execute_callable
    return self.python_callable(*self.op_args, **self.op_kwargs)
           ^^^^^^^^^^^^^^^^^^^^^^^^^^^^^^^^^^^^^^^^^^^^^^^^^^^^^
  File "/opt/airflow/plugins/utils/categorize_pages.py", line 69, in categorize_pages
    category = classify_page_with_llm(page)
               ^^^^^^^^^^^^^^^^^^^^^^^^^^^^
  File "/opt/airflow/plugins/category.py", line 111, in classify_page_with_llm
    result = call_ollama_api(clean_title, CATEGORY_SYSTEM_PROMPT, model)
                                          ^^^^^^^^^^^^^^^^^^^^^^
NameError: name 'CATEGORY_SYSTEM_PROMPT' is not defined
[2025-10-19T18:09:23.678+0000] {taskinstance.py:1205} INFO - Marking task as UP_FOR_RETRY. dag_id=wiki_trending_pipeline, task_id=categorize_pages, execution_date=20251018T000000, start_date=20251019T180921, end_date=20251019T180923
[2025-10-19T18:09:23.723+0000] {standard_task_runner.py:110} ERROR - Failed to execute job 15 for task categorize_pages (name 'CATEGORY_SYSTEM_PROMPT' is not defined; 1338)
[2025-10-19T18:09:23.814+0000] {local_task_job_runner.py:240} INFO - Task exited with return code 1
[2025-10-19T18:09:23.888+0000] {taskinstance.py:3482} INFO - 0 downstream tasks scheduled from follow-on schedule check
[2025-10-19T18:09:23.891+0000] {local_task_job_runner.py:222} INFO - ::endgroup::
