[2025-10-19T12:21:55.964+0000] {local_task_job_runner.py:120} INFO - ::group::Pre task execution logs
[2025-10-19T12:21:56.010+0000] {taskinstance.py:2073} INFO - Dependencies all met for dep_context=non-requeueable deps ti=<TaskInstance: wiki_trending_pipeline.categorize_pages scheduled__2025-10-18T00:00:00+00:00 [queued]>
[2025-10-19T12:21:56.023+0000] {taskinstance.py:2073} INFO - Dependencies all met for dep_context=requeueable deps ti=<TaskInstance: wiki_trending_pipeline.categorize_pages scheduled__2025-10-18T00:00:00+00:00 [queued]>
[2025-10-19T12:21:56.023+0000] {taskinstance.py:2303} INFO - Starting attempt 1 of 3
[2025-10-19T12:21:56.040+0000] {taskinstance.py:2327} INFO - Executing <Task(PythonOperator): categorize_pages> on 2025-10-18 00:00:00+00:00
[2025-10-19T12:21:56.053+0000] {standard_task_runner.py:63} INFO - Started process 664 to run task
[2025-10-19T12:21:56.057+0000] {standard_task_runner.py:90} INFO - Running: ['***', 'tasks', 'run', 'wiki_trending_pipeline', 'categorize_pages', 'scheduled__2025-10-18T00:00:00+00:00', '--job-id', '9', '--raw', '--subdir', 'DAGS_FOLDER/wiki_top_pages_dag.py', '--cfg-path', '/tmp/tmpcphmgmf2']
[2025-10-19T12:21:56.060+0000] {standard_task_runner.py:91} INFO - Job 9: Subtask categorize_pages
[2025-10-19T12:21:56.147+0000] {task_command.py:426} INFO - Running <TaskInstance: wiki_trending_pipeline.categorize_pages scheduled__2025-10-18T00:00:00+00:00 [running]> on host 6045c73eb554
[2025-10-19T12:21:56.297+0000] {taskinstance.py:2644} INFO - Exporting env vars: AIRFLOW_CTX_DAG_OWNER='data-engineering' AIRFLOW_CTX_DAG_ID='wiki_trending_pipeline' AIRFLOW_CTX_TASK_ID='categorize_pages' AIRFLOW_CTX_EXECUTION_DATE='2025-10-18T00:00:00+00:00' AIRFLOW_CTX_TRY_NUMBER='1' AIRFLOW_CTX_DAG_RUN_ID='scheduled__2025-10-18T00:00:00+00:00'
[2025-10-19T12:21:56.299+0000] {taskinstance.py:430} INFO - ::endgroup::
[2025-10-19T12:21:56.336+0000] {logging_mixin.py:188} INFO - ‚ùå Ollama not accessible: HTTPConnectionPool(host='host.docker.internal', port=11434): Max retries exceeded with url: /api/tags (Caused by NewConnectionError('<urllib3.connection.HTTPConnection object at 0x7cc1fbfdaa50>: Failed to establish a new connection: [Errno -2] Name or service not known'))
[2025-10-19T12:21:56.337+0000] {logging_mixin.py:188} INFO -    Make sure to run: ollama serve
[2025-10-19T12:21:56.337+0000] {taskinstance.py:441} INFO - ::group::Post task execution logs
[2025-10-19T12:21:56.338+0000] {taskinstance.py:2890} ERROR - Task failed with exception
Traceback (most recent call last):
  File "/home/airflow/.local/lib/python3.11/site-packages/airflow/models/taskinstance.py", line 465, in _execute_task
    result = _execute_callable(context=context, **execute_callable_kwargs)
             ^^^^^^^^^^^^^^^^^^^^^^^^^^^^^^^^^^^^^^^^^^^^^^^^^^^^^^^^^^^^^
  File "/home/airflow/.local/lib/python3.11/site-packages/airflow/models/taskinstance.py", line 432, in _execute_callable
    return execute_callable(context=context, **execute_callable_kwargs)
           ^^^^^^^^^^^^^^^^^^^^^^^^^^^^^^^^^^^^^^^^^^^^^^^^^^^^^^^^^^^^
  File "/home/airflow/.local/lib/python3.11/site-packages/airflow/models/baseoperator.py", line 400, in wrapper
    return func(self, *args, **kwargs)
           ^^^^^^^^^^^^^^^^^^^^^^^^^^^
  File "/home/airflow/.local/lib/python3.11/site-packages/airflow/operators/python.py", line 235, in execute
    return_value = self.execute_callable()
                   ^^^^^^^^^^^^^^^^^^^^^^^
  File "/home/airflow/.local/lib/python3.11/site-packages/airflow/operators/python.py", line 252, in execute_callable
    return self.python_callable(*self.op_args, **self.op_kwargs)
           ^^^^^^^^^^^^^^^^^^^^^^^^^^^^^^^^^^^^^^^^^^^^^^^^^^^^^
  File "/opt/airflow/plugins/utils/categorize_pages.py", line 30, in categorize_pages
    raise Exception("Ollama not running. Start with: ollama serve")
Exception: Ollama not running. Start with: ollama serve
[2025-10-19T12:21:56.357+0000] {taskinstance.py:1205} INFO - Marking task as UP_FOR_RETRY. dag_id=wiki_trending_pipeline, task_id=categorize_pages, execution_date=20251018T000000, start_date=20251019T122156, end_date=20251019T122156
[2025-10-19T12:21:56.380+0000] {standard_task_runner.py:110} ERROR - Failed to execute job 9 for task categorize_pages (Ollama not running. Start with: ollama serve; 664)
[2025-10-19T12:21:56.430+0000] {local_task_job_runner.py:240} INFO - Task exited with return code 1
[2025-10-19T12:21:56.490+0000] {taskinstance.py:3482} INFO - 0 downstream tasks scheduled from follow-on schedule check
[2025-10-19T12:21:56.492+0000] {local_task_job_runner.py:222} INFO - ::endgroup::
[2025-10-19T18:04:18.022+0000] {local_task_job_runner.py:120} INFO - ::group::Pre task execution logs
[2025-10-19T18:04:18.089+0000] {taskinstance.py:2073} INFO - Dependencies all met for dep_context=non-requeueable deps ti=<TaskInstance: wiki_trending_pipeline.categorize_pages scheduled__2025-10-18T00:00:00+00:00 [queued]>
[2025-10-19T18:04:18.105+0000] {taskinstance.py:2073} INFO - Dependencies all met for dep_context=requeueable deps ti=<TaskInstance: wiki_trending_pipeline.categorize_pages scheduled__2025-10-18T00:00:00+00:00 [queued]>
[2025-10-19T18:04:18.105+0000] {taskinstance.py:2303} INFO - Starting attempt 1 of 3
[2025-10-19T18:04:18.130+0000] {taskinstance.py:2327} INFO - Executing <Task(PythonOperator): categorize_pages> on 2025-10-18 00:00:00+00:00
[2025-10-19T18:04:18.148+0000] {standard_task_runner.py:63} INFO - Started process 960 to run task
[2025-10-19T18:04:18.154+0000] {standard_task_runner.py:90} INFO - Running: ['***', 'tasks', 'run', 'wiki_trending_pipeline', 'categorize_pages', 'scheduled__2025-10-18T00:00:00+00:00', '--job-id', '10', '--raw', '--subdir', 'DAGS_FOLDER/wiki_top_pages_dag.py', '--cfg-path', '/tmp/tmpq29hquo7']
[2025-10-19T18:04:18.157+0000] {standard_task_runner.py:91} INFO - Job 10: Subtask categorize_pages
[2025-10-19T18:04:18.300+0000] {task_command.py:426} INFO - Running <TaskInstance: wiki_trending_pipeline.categorize_pages scheduled__2025-10-18T00:00:00+00:00 [running]> on host fd86742dd253
[2025-10-19T18:04:19.102+0000] {taskinstance.py:2644} INFO - Exporting env vars: AIRFLOW_CTX_DAG_OWNER='data-engineering' AIRFLOW_CTX_DAG_ID='wiki_trending_pipeline' AIRFLOW_CTX_TASK_ID='categorize_pages' AIRFLOW_CTX_EXECUTION_DATE='2025-10-18T00:00:00+00:00' AIRFLOW_CTX_TRY_NUMBER='1' AIRFLOW_CTX_DAG_RUN_ID='scheduled__2025-10-18T00:00:00+00:00'
[2025-10-19T18:04:19.102+0000] {taskinstance.py:430} INFO - ::endgroup::
[2025-10-19T18:04:19.152+0000] {logging_mixin.py:188} INFO - ‚úÖ Ollama is running on host
[2025-10-19T18:04:19.186+0000] {logging_mixin.py:188} INFO - üìä Categorizing: cleaned_2025_10_18.csv
[2025-10-19T18:04:19.369+0000] {logging_mixin.py:188} INFO - ‚úì Created bucket 'gold'
[2025-10-19T18:04:19.439+0000] {logging_mixin.py:188} INFO - ‚úì Loaded 996 pages
[2025-10-19T18:04:19.440+0000] {logging_mixin.py:188} INFO - ü§ñ Classifying with Ollama...
[2025-10-19T18:04:19.447+0000] {taskinstance.py:441} INFO - ::group::Post task execution logs
[2025-10-19T18:04:19.448+0000] {taskinstance.py:2890} ERROR - Task failed with exception
Traceback (most recent call last):
  File "/home/airflow/.local/lib/python3.11/site-packages/airflow/models/taskinstance.py", line 465, in _execute_task
    result = _execute_callable(context=context, **execute_callable_kwargs)
             ^^^^^^^^^^^^^^^^^^^^^^^^^^^^^^^^^^^^^^^^^^^^^^^^^^^^^^^^^^^^^
  File "/home/airflow/.local/lib/python3.11/site-packages/airflow/models/taskinstance.py", line 432, in _execute_callable
    return execute_callable(context=context, **execute_callable_kwargs)
           ^^^^^^^^^^^^^^^^^^^^^^^^^^^^^^^^^^^^^^^^^^^^^^^^^^^^^^^^^^^^
  File "/home/airflow/.local/lib/python3.11/site-packages/airflow/models/baseoperator.py", line 400, in wrapper
    return func(self, *args, **kwargs)
           ^^^^^^^^^^^^^^^^^^^^^^^^^^^
  File "/home/airflow/.local/lib/python3.11/site-packages/airflow/operators/python.py", line 235, in execute
    return_value = self.execute_callable()
                   ^^^^^^^^^^^^^^^^^^^^^^^
  File "/home/airflow/.local/lib/python3.11/site-packages/airflow/operators/python.py", line 252, in execute_callable
    return self.python_callable(*self.op_args, **self.op_kwargs)
           ^^^^^^^^^^^^^^^^^^^^^^^^^^^^^^^^^^^^^^^^^^^^^^^^^^^^^
  File "/opt/airflow/plugins/utils/categorize_pages.py", line 69, in categorize_pages
    category = classify_page_with_llm(page)
               ^^^^^^^^^^^^^^^^^^^^^^^^^^^^
  File "/opt/airflow/plugins/category.py", line 111, in classify_page_with_llm
    result = call_ollama_api(clean_title, CATEGORY_SYSTEM_PROMPT, model)
                                          ^^^^^^^^^^^^^^^^^^^^^^
NameError: name 'CATEGORY_SYSTEM_PROMPT' is not defined
[2025-10-19T18:04:19.472+0000] {taskinstance.py:1205} INFO - Marking task as UP_FOR_RETRY. dag_id=wiki_trending_pipeline, task_id=categorize_pages, execution_date=20251018T000000, start_date=20251019T180418, end_date=20251019T180419
[2025-10-19T18:04:19.497+0000] {standard_task_runner.py:110} ERROR - Failed to execute job 10 for task categorize_pages (name 'CATEGORY_SYSTEM_PROMPT' is not defined; 960)
[2025-10-19T18:04:19.542+0000] {local_task_job_runner.py:240} INFO - Task exited with return code 1
[2025-10-19T18:04:19.602+0000] {taskinstance.py:3482} INFO - 0 downstream tasks scheduled from follow-on schedule check
[2025-10-19T18:04:19.605+0000] {local_task_job_runner.py:222} INFO - ::endgroup::
