[2025-10-19T14:52:38.386+0000] {local_task_job_runner.py:120} INFO - ::group::Pre task execution logs
[2025-10-19T14:52:38.458+0000] {taskinstance.py:2073} INFO - Dependencies all met for dep_context=non-requeueable deps ti=<TaskInstance: wiki_trending_pipeline.check_ollama manual__2025-10-19T14:45:10.219440+00:00 [queued]>
[2025-10-19T14:52:38.469+0000] {taskinstance.py:2073} INFO - Dependencies all met for dep_context=requeueable deps ti=<TaskInstance: wiki_trending_pipeline.check_ollama manual__2025-10-19T14:45:10.219440+00:00 [queued]>
[2025-10-19T14:52:38.469+0000] {taskinstance.py:2303} INFO - Starting attempt 1 of 3
[2025-10-19T14:52:38.484+0000] {taskinstance.py:2327} INFO - Executing <Task(PythonOperator): check_ollama> on 2025-10-19 14:45:10.219440+00:00
[2025-10-19T14:52:38.498+0000] {standard_task_runner.py:63} INFO - Started process 496 to run task
[2025-10-19T14:52:38.501+0000] {standard_task_runner.py:90} INFO - Running: ['***', 'tasks', 'run', 'wiki_trending_pipeline', 'check_ollama', 'manual__2025-10-19T14:45:10.219440+00:00', '--job-id', '47', '--raw', '--subdir', 'DAGS_FOLDER/wiki_top_pages_dag.py', '--cfg-path', '/tmp/tmp5ixebba3']
[2025-10-19T14:52:38.504+0000] {standard_task_runner.py:91} INFO - Job 47: Subtask check_ollama
[2025-10-19T14:52:38.570+0000] {task_command.py:426} INFO - Running <TaskInstance: wiki_trending_pipeline.check_ollama manual__2025-10-19T14:45:10.219440+00:00 [running]> on host 6045c73eb554
[2025-10-19T14:52:38.725+0000] {taskinstance.py:2644} INFO - Exporting env vars: AIRFLOW_CTX_DAG_OWNER='data-engineering' AIRFLOW_CTX_DAG_ID='wiki_trending_pipeline' AIRFLOW_CTX_TASK_ID='check_ollama' AIRFLOW_CTX_EXECUTION_DATE='2025-10-19T14:45:10.219440+00:00' AIRFLOW_CTX_TRY_NUMBER='1' AIRFLOW_CTX_DAG_RUN_ID='manual__2025-10-19T14:45:10.219440+00:00'
[2025-10-19T14:52:38.726+0000] {taskinstance.py:430} INFO - ::endgroup::
[2025-10-19T14:52:38.782+0000] {logging_mixin.py:188} INFO - ‚ùå Ollama not accessible: HTTPConnectionPool(host='host.docker.internal', port=11434): Max retries exceeded with url: /api/tags (Caused by NewConnectionError('<urllib3.connection.HTTPConnection object at 0x78559d168c10>: Failed to establish a new connection: [Errno -2] Name or service not known'))
[2025-10-19T14:52:38.782+0000] {logging_mixin.py:188} INFO -    Make sure to run: ollama serve
[2025-10-19T14:52:38.783+0000] {python.py:237} INFO - Done. Returned value was: False
[2025-10-19T14:52:38.784+0000] {taskinstance.py:441} INFO - ::group::Post task execution logs
[2025-10-19T14:52:38.860+0000] {taskinstance.py:1205} INFO - Marking task as SUCCESS. dag_id=wiki_trending_pipeline, task_id=check_ollama, execution_date=20251019T144510, start_date=20251019T145238, end_date=20251019T145238
[2025-10-19T14:52:38.914+0000] {local_task_job_runner.py:240} INFO - Task exited with return code 0
[2025-10-19T14:52:38.952+0000] {taskinstance.py:3482} INFO - 1 downstream tasks scheduled from follow-on schedule check
[2025-10-19T14:52:38.954+0000] {local_task_job_runner.py:222} INFO - ::endgroup::
