[2025-10-19T14:55:23.707+0000] {local_task_job_runner.py:120} INFO - ::group::Pre task execution logs
[2025-10-19T14:55:23.778+0000] {taskinstance.py:2073} INFO - Dependencies all met for dep_context=non-requeueable deps ti=<TaskInstance: wiki_trending_pipeline.check_ollama manual__2025-10-19T14:54:28.659389+00:00 [queued]>
[2025-10-19T14:55:23.791+0000] {taskinstance.py:2073} INFO - Dependencies all met for dep_context=requeueable deps ti=<TaskInstance: wiki_trending_pipeline.check_ollama manual__2025-10-19T14:54:28.659389+00:00 [queued]>
[2025-10-19T14:55:23.792+0000] {taskinstance.py:2303} INFO - Starting attempt 1 of 3
[2025-10-19T14:55:23.812+0000] {taskinstance.py:2327} INFO - Executing <Task(PythonOperator): check_ollama> on 2025-10-19 14:54:28.659389+00:00
[2025-10-19T14:55:23.827+0000] {standard_task_runner.py:63} INFO - Started process 1026 to run task
[2025-10-19T14:55:23.832+0000] {standard_task_runner.py:90} INFO - Running: ['***', 'tasks', 'run', 'wiki_trending_pipeline', 'check_ollama', 'manual__2025-10-19T14:54:28.659389+00:00', '--job-id', '52', '--raw', '--subdir', 'DAGS_FOLDER/wiki_top_pages_dag.py', '--cfg-path', '/tmp/tmpix9dxlhx']
[2025-10-19T14:55:23.836+0000] {standard_task_runner.py:91} INFO - Job 52: Subtask check_ollama
[2025-10-19T14:55:23.934+0000] {task_command.py:426} INFO - Running <TaskInstance: wiki_trending_pipeline.check_ollama manual__2025-10-19T14:54:28.659389+00:00 [running]> on host 6045c73eb554
[2025-10-19T14:55:24.101+0000] {taskinstance.py:2644} INFO - Exporting env vars: AIRFLOW_CTX_DAG_OWNER='data-engineering' AIRFLOW_CTX_DAG_ID='wiki_trending_pipeline' AIRFLOW_CTX_TASK_ID='check_ollama' AIRFLOW_CTX_EXECUTION_DATE='2025-10-19T14:54:28.659389+00:00' AIRFLOW_CTX_TRY_NUMBER='1' AIRFLOW_CTX_DAG_RUN_ID='manual__2025-10-19T14:54:28.659389+00:00'
[2025-10-19T14:55:24.102+0000] {taskinstance.py:430} INFO - ::endgroup::
[2025-10-19T14:55:24.145+0000] {logging_mixin.py:188} INFO - ‚ùå Ollama not accessible: HTTPConnectionPool(host='host.docker.internal', port=11434): Max retries exceeded with url: /api/tags (Caused by NewConnectionError('<urllib3.connection.HTTPConnection object at 0x7855b5faa110>: Failed to establish a new connection: [Errno -2] Name or service not known'))
[2025-10-19T14:55:24.146+0000] {logging_mixin.py:188} INFO -    Make sure to run: ollama serve
[2025-10-19T14:55:24.146+0000] {python.py:237} INFO - Done. Returned value was: False
[2025-10-19T14:55:24.147+0000] {taskinstance.py:441} INFO - ::group::Post task execution logs
[2025-10-19T14:55:24.199+0000] {taskinstance.py:1205} INFO - Marking task as SUCCESS. dag_id=wiki_trending_pipeline, task_id=check_ollama, execution_date=20251019T145428, start_date=20251019T145523, end_date=20251019T145524
[2025-10-19T14:55:24.285+0000] {local_task_job_runner.py:240} INFO - Task exited with return code 0
[2025-10-19T14:55:24.335+0000] {taskinstance.py:3482} INFO - 1 downstream tasks scheduled from follow-on schedule check
[2025-10-19T14:55:24.337+0000] {local_task_job_runner.py:222} INFO - ::endgroup::
