[2025-10-19T14:52:39.376+0000] {local_task_job_runner.py:120} INFO - ::group::Pre task execution logs
[2025-10-19T14:52:39.429+0000] {taskinstance.py:2073} INFO - Dependencies all met for dep_context=non-requeueable deps ti=<TaskInstance: wiki_trending_pipeline.categorize_pages manual__2025-10-19T14:45:10.219440+00:00 [queued]>
[2025-10-19T14:52:39.441+0000] {taskinstance.py:2073} INFO - Dependencies all met for dep_context=requeueable deps ti=<TaskInstance: wiki_trending_pipeline.categorize_pages manual__2025-10-19T14:45:10.219440+00:00 [queued]>
[2025-10-19T14:52:39.441+0000] {taskinstance.py:2303} INFO - Starting attempt 1 of 3
[2025-10-19T14:52:39.453+0000] {taskinstance.py:2327} INFO - Executing <Task(PythonOperator): categorize_pages> on 2025-10-19 14:45:10.219440+00:00
[2025-10-19T14:52:39.463+0000] {standard_task_runner.py:63} INFO - Started process 498 to run task
[2025-10-19T14:52:39.469+0000] {standard_task_runner.py:90} INFO - Running: ['***', 'tasks', 'run', 'wiki_trending_pipeline', 'categorize_pages', 'manual__2025-10-19T14:45:10.219440+00:00', '--job-id', '48', '--raw', '--subdir', 'DAGS_FOLDER/wiki_top_pages_dag.py', '--cfg-path', '/tmp/tmphcrvyqa2']
[2025-10-19T14:52:39.474+0000] {standard_task_runner.py:91} INFO - Job 48: Subtask categorize_pages
[2025-10-19T14:52:39.549+0000] {task_command.py:426} INFO - Running <TaskInstance: wiki_trending_pipeline.categorize_pages manual__2025-10-19T14:45:10.219440+00:00 [running]> on host 6045c73eb554
[2025-10-19T14:52:39.738+0000] {taskinstance.py:2644} INFO - Exporting env vars: AIRFLOW_CTX_DAG_OWNER='data-engineering' AIRFLOW_CTX_DAG_ID='wiki_trending_pipeline' AIRFLOW_CTX_TASK_ID='categorize_pages' AIRFLOW_CTX_EXECUTION_DATE='2025-10-19T14:45:10.219440+00:00' AIRFLOW_CTX_TRY_NUMBER='1' AIRFLOW_CTX_DAG_RUN_ID='manual__2025-10-19T14:45:10.219440+00:00'
[2025-10-19T14:52:39.739+0000] {taskinstance.py:430} INFO - ::endgroup::
[2025-10-19T14:52:39.785+0000] {logging_mixin.py:188} INFO - ‚ùå Ollama not accessible: HTTPConnectionPool(host='host.docker.internal', port=11434): Max retries exceeded with url: /api/tags (Caused by NewConnectionError('<urllib3.connection.HTTPConnection object at 0x7855b5fa98d0>: Failed to establish a new connection: [Errno -2] Name or service not known'))
[2025-10-19T14:52:39.786+0000] {logging_mixin.py:188} INFO -    Make sure to run: ollama serve
[2025-10-19T14:52:39.786+0000] {taskinstance.py:441} INFO - ::group::Post task execution logs
[2025-10-19T14:52:39.786+0000] {taskinstance.py:2890} ERROR - Task failed with exception
Traceback (most recent call last):
  File "/home/airflow/.local/lib/python3.11/site-packages/airflow/models/taskinstance.py", line 465, in _execute_task
    result = _execute_callable(context=context, **execute_callable_kwargs)
             ^^^^^^^^^^^^^^^^^^^^^^^^^^^^^^^^^^^^^^^^^^^^^^^^^^^^^^^^^^^^^
  File "/home/airflow/.local/lib/python3.11/site-packages/airflow/models/taskinstance.py", line 432, in _execute_callable
    return execute_callable(context=context, **execute_callable_kwargs)
           ^^^^^^^^^^^^^^^^^^^^^^^^^^^^^^^^^^^^^^^^^^^^^^^^^^^^^^^^^^^^
  File "/home/airflow/.local/lib/python3.11/site-packages/airflow/models/baseoperator.py", line 400, in wrapper
    return func(self, *args, **kwargs)
           ^^^^^^^^^^^^^^^^^^^^^^^^^^^
  File "/home/airflow/.local/lib/python3.11/site-packages/airflow/operators/python.py", line 235, in execute
    return_value = self.execute_callable()
                   ^^^^^^^^^^^^^^^^^^^^^^^
  File "/home/airflow/.local/lib/python3.11/site-packages/airflow/operators/python.py", line 252, in execute_callable
    return self.python_callable(*self.op_args, **self.op_kwargs)
           ^^^^^^^^^^^^^^^^^^^^^^^^^^^^^^^^^^^^^^^^^^^^^^^^^^^^^
  File "/opt/airflow/plugins/utils/categorize_pages.py", line 30, in categorize_pages
    raise Exception("Ollama not running. Start with: ollama serve")
Exception: Ollama not running. Start with: ollama serve
[2025-10-19T14:52:39.814+0000] {taskinstance.py:1205} INFO - Marking task as UP_FOR_RETRY. dag_id=wiki_trending_pipeline, task_id=categorize_pages, execution_date=20251019T144510, start_date=20251019T145239, end_date=20251019T145239
[2025-10-19T14:52:39.831+0000] {standard_task_runner.py:110} ERROR - Failed to execute job 48 for task categorize_pages (Ollama not running. Start with: ollama serve; 498)
[2025-10-19T14:52:39.879+0000] {local_task_job_runner.py:240} INFO - Task exited with return code 1
[2025-10-19T14:52:39.957+0000] {taskinstance.py:3482} INFO - 0 downstream tasks scheduled from follow-on schedule check
[2025-10-19T14:52:39.958+0000] {local_task_job_runner.py:222} INFO - ::endgroup::
